<?xml version="1.0" ?>
<sdf version="1.9">
  <model name="micro_drone">
    <static>false</static>
    <self_collide>false</self_collide>
    <allow_auto_disable>false</allow_auto_disable>

    <!-- Основной корпус -->
    <link name="base_link">
      <pose>0 0 0 0 0 0</pose>
      <collision name="collision">
        <geometry>
          <box>
            <size>0.2 0.2 0.05</size>
          </box>
        </geometry>
      </collision>
      <visual name="visual">
        <geometry>
          <box>
            <size>0.2 0.2 0.05</size>
          </box>
        </geometry>
        <material>
          <ambient>0.2 0.2 0.7 1</ambient>
          <diffuse>0.2 0.2 0.7 1</diffuse>
        </material>
      </visual>
      <inertial>
        <mass>0.3</mass>
        <inertia>
          <ixx>0.001</ixx>
          <iyy>0.001</iyy>
          <izz>0.002</izz>
        </inertia>
      </inertial>
    </link>

    <!-- Камера -->
    <link name="camera_link">
      <pose>0 0 0.05 0 0 0</pose>
      <sensor name="mono_camera" type="camera">
        <pose>0 0 0 0 0 0</pose>
        <camera>
          <horizontal_fov>1.57</horizontal_fov>
          <image>
            <width>640</width>
            <height>480</height>
            <format>R8G8B8</format>
          </image>
          <clip>
            <near>0.1</near>
            <far>20</far>
          </clip>
        </camera>
        <always_on>true</always_on>
        <update_rate>30</update_rate>
        <visualize>true</visualize>
      </sensor>
    </link>

    <!-- Жёсткое соединение камеры -->
    <joint name="cam_joint" type="fixed">
      <parent>base_link</parent>
      <child>camera_link</child>
    </joint>

    <!-- 4 ротора -->
    <!-- rotor_0 -->
    <link name="rotor_0"/>
    <joint name="rotor_0_joint" type="revolute">
      <parent>base_link</parent>
      <child>rotor_0</child>
      <axis>
        <xyz>0 0 1</xyz>
        <limit><effort>0.1</effort></limit>
      </axis>
    </joint>
    <plugin name="motor_0" filename="gz-sim-multicopter-motor-model-system">
      <jointName>rotor_0_joint</jointName>
      <linkName>rotor_0</linkName>
      <turningDirection>ccw</turningDirection>
      <motorNumber>0</motorNumber>
      <motorType>velocity</motorType>
      <commandSubTopic>command/motor_speed</commandSubTopic>
    </plugin>

    <!-- rotor_1 -->
    <link name="rotor_1"/>
    <joint name="rotor_1_joint" type="revolute">
      <parent>base_link</parent>
      <child>rotor_1</child>
      <axis>
        <xyz>0 0 1</xyz>
        <limit><effort>0.1</effort></limit>
      </axis>
    </joint>
    <plugin name="motor_1" filename="gz-sim-multicopter-motor-model-system">
      <jointName>rotor_1_joint</jointName>
      <linkName>rotor_1</linkName>
      <turningDirection>cw</turningDirection>
      <motorNumber>1</motorNumber>
      <motorType>velocity</motorType>
      <commandSubTopic>command/motor_speed</commandSubTopic>
    </plugin>

    <!-- rotor_2 -->
    <link name="rotor_2"/>
    <joint name="rotor_2_joint" type="revolute">
      <parent>base_link</parent>
      <child>rotor_2</child>
      <axis>
        <xyz>0 0 1</xyz>
        <limit><effort>0.1</effort></limit>
      </axis>
    </joint>
    <plugin name="motor_2" filename="gz-sim-multicopter-motor-model-system">
      <jointName>rotor_2_joint</jointName>
      <linkName>rotor_2</linkName>
      <turningDirection>ccw</turningDirection>
      <motorNumber>2</motorNumber>
      <motorType>velocity</motorType>
      <commandSubTopic>command/motor_speed</commandSubTopic>
    </plugin>

    <!-- rotor_3 -->
    <link name="rotor_3"/>
    <joint name="rotor_3_joint" type="revolute">
      <parent>base_link</parent>
      <child>rotor_3</child>
      <axis>
        <xyz>0 0 1</xyz>
        <limit><effort>0.1</effort></limit>
      </axis>
    </joint>
    <plugin name="motor_3" filename="gz-sim-multicopter-motor-model-system">
      <jointName>rotor_3_joint</jointName>
      <linkName>rotor_3</linkName>
      <turningDirection>cw</turningDirection>
      <motorNumber>3</motorNumber>
      <motorType>velocity</motorType>
      <commandSubTopic>command/motor_speed</commandSubTopic>
    </plugin>

    <!-- Одометрия -->
    <plugin name="odometry_publisher" filename="gz-sim-odometry-publisher-system">
      <dimensions>3</dimensions>
    </plugin>
  </model>
</sdf>
